Workbook

Sheet Changes Historic
A1: Date | B1: Modified WP/Task | C1: NAME WP/Task/MI | D1: Change | E1: Summary of modification | F1: #New Version
A2: 44118 | B2: W. 3.2 | C2: Mold manufacturing | D2: Responsible | E2: Mock information | F2: Mock code 1
A3: 44131 | B3: W. 3.2 | C3: Mold manufacturing | D3: How to do | E3: Mock information | F3: Mock code 2
A4: 44153 | B4: WP 2.1 | C4: Product definition | D4: How to do | E4: Mock information | F4: Mock code 3
A5: 44180 | B5: WP 2.3 | C5: Confirm Logistics feasibility | D5: How to do | E5: Mock information | F5: Mock code 4
A6: 44180 | B6: WP 4.2 | C6: Logistics preparation | D6: How to do | E6: Mock information | F6: Mock code 5
A7: 44210 | B7: WP 4.1 | C7: Product verification | D7: How to do | E7: Mock information | F7: Mock code 6
A8: 44210 | B8: WP 4.1 | C8: Product improvement | D8: How to do | E8: Mock information | F8: Mock code 7
A9: 44214 | B9: M1 and M2 | C9: M1 | D9: How to do | E9: Mock information | F9: Mock code 8
A10: 44214 | B10: WP 3.1 | C10: Purchase components | D10: How to do | E10: Mock information | F10: Mock code 9
A11: 44221 | B11: WP 1.1 | C11: Prepare preliminary project data and targets | D11: Output | E11: Mock information | F11: Mock code 10
A12: 44222 | B12: WP4.2. | C12: IS & PPAP Submission OS | D12: How to do | E12: Mock information | F12: Mock code 11
A13: 44245 | B13: WP 3.1 | C13: Purchase mass production packaging | D13: Name of WP + How to do + Output | E13: Mock information | F13: Mock code 12
... A46: 44467 | B46: WP 2.3 | C46: Confirm Draft Mass Production Packaging | D46: how to do | E46: Mock information | F46: Mock code 45
A47: 44473 | B47: WP 2.3 | C47: Workshop to agree on Product/Process Design | E47: Mock information | F47: Mock code 46
A48: 44476 | B48: WP 4.1 | C48: Product verification | D48: How to do | E48: Mock information | F48: Mock code 47
A49: 44482 | B49: WP 2.2 | C49: Confirm the process meets requirements | D49: all task | E49: Mock information | F49: Mock code 48
A50: 44482 | B50: WP 2.2 | C50: Launch Control plan | D50: added task | E50: Mock information | F50: Mock code 49
A51: 44502 | B51: WP 2.2 | C51: Launch Control plan | D51: how to do | E51: Mock information | F51: Mock code 50
A52: 44522 | B52: M2 | C52: Investmenet agreement | D52: How to do | E52: Mock information | F52: Mock code 51
A53: 44580 | B53: WP. 2.1 | C53: Confirm material feasibility | D53: Output | E53: Mock information | F53: Mock code 52
A54: 44581 | B54: WP 4.1 | C54: Delivieries in preserial phase | D54: how to do | E54: Mock information | F54: Mock code 53
A55: 44594 | B55: WP4.1 | C55: IS & PPAP Submission OS | D55: how to do | E55: Mock information | F55: Mock code 54
A56: 44622 | B56: WP 2.1 | C56: Style frozen | D56: How to do | E56: Mock information | F56: Mock code 55
A57: 44623 | B57: several | C57: several | D57: several | E57: Mock information | F57: Mock code 56
A58: 44628 | B58: WP 4.1 | C58: Product Verification | D58: how to do | E58: Mock information | F58: Mock code 57
A59: 44628 | B59: WP 3.1 | C59: Get Purchasing quotation&nomination | D59: Support/Attendees | E59: Mock information | F59: Mock code 58
... A68: 44753 | B68: WP 4.1 | C68: Logistics preparation | D68: output | E68: Mock information | F68: Mock code 67
A69: 44851 | B69: WP 2.2 Elaboration of specific technical conditions for equipments and RFQ's | D69: How to do / output | E69: Mock information | F69: Mock code 68
A70: 17/10/20220 | B70: WP 2.1 | C70: Assign moldmaker for feasibility | D70: Task deleted | E70: Mock information | F70: Mock code 69
A71: 17/10/20220 | B71: WP 2.1 | C71: Mould feasibility | D71: Task deleted | E71: Mock information | F71: Mock code 70
A72: 44868 | B72: WP 2.3 | C72: Process FMEA | D72: How to do | E72: Mock information | F72: Mock code 71
A73: 44873 | B73: M4 | C73: Mass production agreement | D73: How to do | E73: Mock information | F73: Mock code 72
A74: 44873 | B74: M5 | C74: Project evaluation and closing | D74: How to do | E74: Mock information | F74: Mock code 73
A75: 44900 | B75: WP 4.1 | C75: Validate mass production packaging | D75: How to do | E75: Mock information | F75: Mock code 74
A76: 44571 | B76: M4 | C76: Mass production agreement | D76: HOW TO DO | E76: Mock information | F76: Mock code 75
A77: 44571 | B77: WP 3.1 | C77: Purchase components | D77: how to do | E77: Mock information | F77: Mock code 76
A78: 44937 | B78: several | C78: several | D78: Output | E78: Mock information | F78: Mock code 77
A79: 44938 | B79: WP 4.1 | C79: Process verification & improvement | D79: Output | E79: Mock information | F79: Mock code 78
A80: 44938 | B80: WP 4.1 | C80: IS & PPAP Submission | D80: how to do | E80: Mock information | F80: Mock code 79
...

Sheet Legend
A1: Abbr. / Color | B1: Meaning
B2: Phase 1
B3: Phase 2
B4: Phase 3
B5: Phase 4
B6: Phase 5
A7: Mock abbr. 1 | B7: Mock meaning 1
A8: Mock abbr. 2 | B8: Mock meaning 2
A9: Mock abbr. 3 | B9: Mock meaning 3
A10: Mock abbr. 4 | B10: Mock meaning 4
A11: Mock abbr. 5 | B11: Mock meaning 5
A12: Mock abbr. 6 | B12: Mock meaning 6
A13: Mock abbr. 7 | B13: Mock meaning 7
A14: Mock abbr. 8 | B14: Mock meaning 8
A15: Mock abbr. 9 | B15: Mock meaning 9
A16: Mock abbr. 10 | B16: Mock meaning 10
A17: Mock abbr. 11 | B17: Mock meaning 11
A18: Mock abbr. 12 | B18: Mock meaning 12
... A50: Mock abbr. 44 | B50: Mock meaning 44

Sheet Instr. template
A1: Task | B1: Verb+Direct Object
A2: Objective | B2: Goal or benefit
A3: Input | B3: Documents and location
A4: Responsible | B4: This person is the responsible to this task. A person who has enough capability: technical, action and decision. This person must close the task in ZITA (Task manager". He/She could ask for support to the defined people in "Support" field.
A5: Support/Attendees | B5: People that may participate and help on the execution/In the tasks that it is need a meeting these roles are the attendees.
A6: How to do | B6: List of acction. Recomendation: verb+Direct Object+ tools that have to be used. Identify loops.
A7: Assessment | B7: Requiered conditions to close the task.
A8: Output | B8: Records or files and location/folder to store the documentation in PDM (Project Data Managment).
A9: Signatures | B9: In case of the output document requires signatures: 1. Digital signatures in PDM: "Name Document" +List of the roles that should sign this document 2. Signatures in PDF: signature of the responsible of the document in the PDF file
A10: Special cases | B10: Defined roles may allowed a deviation in "How to do".
A11: Version number | B11: YYYYMMDD VXXX

Sheet HOW TO USE DOCUMENT
A6: # | B6: SHEET NAMES | C6: COMMENTS
A7: 1 | B7: Changes Historic | C7: List of the main changes in the DOCUMENT instructions
A8: 2 | B8: Legend | C8: Abbreviations and color used and the meaning
A9: 3 | B9: Instr. Template | C9: Explanation of the template that is used for the instructions
A10: 4 | B10: Extra information | C10: Extra information of the instructions: example: "Trial management"
A11: 5 | B11: HOW TO USE WBS EXCEL | C11: This sheet with the explanation of every sheet of this file
A12: 6 | B12: EQUIVALENCES | C12: Summary of the main equivalences between the previous Project Workflow and the new document.
A13: 7 | B13: PDM Structure | C13: Summary of the PDM structure: folders, subfolders and documents
A14: 6 | B14: WBS DEF | C14: Working Breakdown Structure
A15: 7 | B15: WP's&M's REVIEW | C15: Summary of the Working Packging (WP's), Milestones (MI's) and tasks that are defined in the document. Double click in the abbreviation in "column I" to go directly to the corresponding sheet of the estándar/instruction. All the WP Sheets and Instrucctions are linked to this sheet: "WP's&M's REVIEW" (click the yelow rectangle)
A16: 8 | B16: "WPX.Y. (X=Phase and Y=correlative number of the WP) + "Abbreviation of the achievement" | C16: Working Package In each WP there is the corresponding diagram. The colour of each sheet depends on the project phase.
A17: 9 | B17: Abbreviation of the achievement | C17: Correnponding sheeet of the instruction. The colour of each sheet depends on the project phase.
A18: 10 | B18: MX.(X=Phase)+ "Abbreviation of the achievement" | C18: Instruction of each Milestone. The colour of each sheet depends on the project phase.

Sheet EQUIVALENCES
B1: Phase 1 | C1: Phase 2 | D1: Phase 3 | E1: Phase 4 | F1: Phase 5
A2: Old system | B2: TR0 | C2: TR1 | D2: TR2 | E2: TR3 + TR4 | F2: TR4 + TR5
A3: New WBS: MILESTONE OR TASK | B3: M1 | C3: M2 | D3: Corrections and adjustments and transfer go-ahead | E3: IS PPAP doc + M4 | F3: Update and file LLC + M5
A4: New WBS: signatures required in PDM | C4: Mock signature members 1 | D4: Mock signature members 2 | E4: Mock signature members 3 | F4: Mock signature members 4

Sheet EQU ZANINI&CUSTOMERS
B1: CUSTOMER EQUIVALENCES
A2: Company | B2: Customer 1 | C2: Customer 2 | D2: Customer 3 | E2: Customer 4 | F2: Customer 5 | G2: Customer 6 | H2: Customer 7 | I2: Customer 8 | J2: Customer 9 | K2: Customer 10 | L2: Customer 11
A3: M1 Project Kick-off | B3: Mock customer 1 code 1 | C3: Mock customer 2 code 1 | D3: Mock customer 3 code 1 | E3: Mock customer 4 code 1 | F3: Mock customer 5 code 1 | G3: Mock customer 6 code 1 | H3: Mock customer 7 code 1 | I3: Mock customer 8 code 1 | J3: Mock customer 9 code 1 | K3: Mock customer 10 code 1 | L3: Mock customer 11 code 1
A4: M2 Invesment agreement | B4: Mock customer 1 code 2 | C4: Mock customer 2 code 2 | D4: Mock customer 3 code 2 | E4: Mock customer 4 code 2 | F4: Mock customer 5 code 2 | G4: Mock customer 6 code 2 | H4: Mock customer 7 code 2 | I4: Mock customer 8 code 2 | J4: Mock customer 9 code 2 | K4: Mock customer 10 code 2 | L4: Mock customer 11 code 2
A5: Client approval (3D + drawing) | B5: Mock customer 1 code 3 | C5: Mock customer 2 code 3 | D5: Mock customer 3 code 3 | E5: Mock customer 4 code 3 | F5: Mock customer 5 code 3 | G5: Mock customer 6 code 3 | H5: Mock customer 7 code 3 | I5: Mock customer 8 code 3 | J5: Mock customer 9 code 3 | K5: Mock customer 10 code 3 | L5: Mock customer 11 code 3
A6: Corrections and adjustments and transfer go-ahead | B6: Mock customer 1 code 4 | C6: Mock customer 2 code 4 | D6: Mock customer 3 code 4 | E6: Mock customer 4 code 4 | F6: Mock customer 5 code 4 | G6: Mock customer 6 code 4 | H6: Mock customer 7 code 4 | I6: Mock customer 8 code 4 | J6: Mock customer 9 code 4 | K6: Mock customer 10 code 4 | L6: Mock customer 11 code 4
A7: IS & PPAP Submission | B7: Mock customer 1 code 5 | C7: Mock customer 2 code 5 | D7: Mock customer 3 code 5 | E7: Mock customer 4 code 5 | F7: Mock customer 5 code 5 | G7: Mock customer 6 code 5 | H7: Mock customer 7 code 5 | I7: Mock customer 8 code 5 | J7: Mock customer 9 code 5 | K7: Mock customer 10 code 5 | L7: Mock customer 11 code 5
A8: Vehicle Builds Shipments OT | B8: Mock customer 1 code 6 | C8: Mock customer 2 code 6 | D8: Mock customer 3 code 6 | E8: Mock customer 4 code 6 | F8: Mock customer 5 code 6 | G8: Mock customer 6 code 6 | H8: Mock customer 7 code 6 | I8: Mock customer 8 code 6 | J8: Mock customer 9 code 6 | K8: Mock customer 10 code 6 | L8: Mock customer 11 code 6
A9: Vehicle Builds Shipments OS | B9: Mock customer 1 code 7 | C9: Mock customer 2 code 7 | D9: Mock customer 3 code 7 | E9: Mock customer 4 code 7 | F9: Mock customer 5 code 7 | G9: Mock customer 6 code 7 | H9: Mock customer 7 code 7 | I9: Mock customer 8 code 7 | J9: Mock customer 9 code 7 | K9: Mock customer 10 code 7 | L9: Mock customer 11 code 7
A10: SOP | B10: Mock customer 1 code 8 | C10: Mock customer 2 code 8 | D10: Mock customer 3 code 8 | E10: Mock customer 4 code 8 | F10: Mock customer 5 code 8 | G10: Mock customer 6 code 8 | H10: Mock customer 7 code 8 | I10: Mock customer 8 code 8 | J10: Mock customer 9 code 8 | K10: Mock customer 10 code 8 | L10: Mock customer 11 code 8
A11: Production Trial Run | B11: Mock customer 1 code 9 | C11: Mock customer 2 code 9 | D11: Mock customer 3 code 9 | E11: Mock customer 4 code 9 | F11: Mock customer 5 code 9 | G11: Mock customer 6 code 9 | H11: Mock customer 7 code 9 | I11: Mock customer 8 code 9 | J11: Mock customer 9 code 9 | K11: Mock customer 10 code 9 | L11: Mock customer 11 code 9
A12: Define Validation Plan | B12: Mock customer 1 code 10 | C12: Mock customer 2 code 10 | D12: Mock customer 3 code 10 | E12: Mock customer 4 code 10 | F12: Mock customer 5 code 10 | G12: Mock customer 6 code 10 | H12: Mock customer 7 code 10 | I12: Mock customer 8 code 10 | J12: Mock customer 9 code 10 | K12: Mock customer 10 code 10 | L12: Mock customer 11 code 10

Sheet PDM Structure
A1: FOLDER | B1: SUBFOLDER | C1: DOCUMENTATION IN PDM | D1: COMMENTS
A2: 00A Project Management | C2: - | D2: -
B3: Mock info subfolder 1 | C3: Mock documentation in PDM 1 | D3: Comments 1
B4: Mock info subfolder 2 | C4: Mock documentation in PDM 2 | D4: Comments 2
B5: Mock info subfolder 3 | C5: Mock documentation in PDM 3 | D5: Comments 3
B6: Mock info subfolder 4 | C6: Mock documentation in PDM 4 | D6: Comments 4
A7: 00B Quotation
B8: Mock info subfolder 5 | C8: Mock documentation in PDM 5 | D8: Comments 5
B9: Mock info subfolder 6 | C9: Mock documentation in PDM 6 | D9: Comments 6
B10: Mock info subfolder 7 | C10: Mock documentation in PDM 7 | D10: Comments 7
A11: 00C Cross-phase documents
B12: Mock info subfolder 8 | C12: Mock documentation in PDM 8 | D12: Comments 8
B13: Mock info subfolder 9 | C13: Mock documentation in PDM 9 | D13: Comments 9
B14: Mock info subfolder 10 | C14: Mock documentation in PDM 10 | D14: Comments 10
B15: Mock info subfolder 11 | C15: Mock documentation in PDM 11 | D15: Comments 11
B16: Mock info subfolder 12 | C16: Mock documentation in PDM 12 | D16: Comments 12
B17: Mock info subfolder 13 | C17: Mock documentation in PDM 13 | D17: Comments 13
B18: Mock info subfolder 14 | C18: Mock documentation in PDM 14 | D18: Comments 14
B19: Mock info subfolder 15 | C19: Mock documentation in PDM 15 | D19: Comments 15
B20: Mock info subfolder 16 | C20: Mock documentation in PDM 16 | D20: Comments 16
B21: Mock info subfolder 17 | C21: Mock documentation in PDM 17 | D21: Comments 17
B22: Mock info subfolder 18 | C22: Mock documentation in PDM 18 | D22: Comments 18
B23: Mock info subfolder 19 | C23: Mock documentation in PDM 19 | D23: Comments 19
B24: Mock info subfolder 20 | C24: Mock documentation in PDM 20 | D24: Comments 20
A25: 01 Project kick-off | C25: M1: Project kick-off agreement file: milestone summary report
A26: 02 WP 2.0 Proto tool phase
B27: Mock info subfolder 21 | C27: Mock documentation in PDM 21 | D27: Comments 21
B28: Mock info subfolder 22 | C28: Mock documentation in PDM 22 | D28: Comments 22
B29: Mock info subfolder 23 | C29: Mock documentation in PDM 23 | D29: Comments 23
B30: Mock info subfolder 24 | C30: Mock documentation in PDM 24 | D30: Comments 24
B31: Mock info subfolder 25 | C31: Mock documentation in PDM 25 | D31: Comments 25
B32: Mock info subfolder 26 | C32: Mock documentation in PDM 26 | D32: Comments 26
B33: Mock info subfolder 27 | C33: Mock documentation in PDM 27 | D33: Comments 27
B34: Mock info subfolder 28 | C34: Mock documentation in PDM 28 | D34: Comments 28
B35: Mock info subfolder 29 | C35: Mock documentation in PDM 29 | D35: Comments 29
B36: Mock info subfolder 30 | C36: Mock documentation in PDM 30 | D36: Comments 30
A37: 02 WP2.1 Product definition
B38: Mock info subfolder 31 | C38: Mock documentation in PDM 31 | D38: Comments 31
B39: Mock info subfolder 32 | C39: Mock documentation in PDM 32 | D39: Comments 32
B40: Mock info subfolder 33 | C40: Mock documentation in PDM 33 | D40: Comments 33
...

Sheet WBS DEF

Sheet WP's&M's REVIEW
A1: PHASE | B1: WP/M | C1: NAME WP/M | D1: ACHIEVEMENTS | E1: R | F1: S | G1: OUTPUT: DOCUMENTS AND PLACE TO STORE | H1: SIGNATURES | I1: ABBREVIATION NAME SHEET INSTRUCCTION
A2: Phase 1 | B2: WP1.1. | C2: ='WP1.1. PJ PREP'!B1 -> Project Management preparation | D2: ='WP1.1. PJ PREP'!B1 -> Project Management preparation | E2: ='WP1.1. PJ PREP'!B4 -> Mock General 003 | F2: ='WP1.1. PJ PREP'!B5 -> Mock General 004 | G2: ='WP1.1. PJ PREP'!B8 -> Mock General 007 | H2: ='WP1.1. PJ PREP'!B9 -> Mock General 008 | I2: WP1.1. PJ PREP
B3: WP1.1. | C3: =C2 -> Project Management preparation | D3: ='Quotation transfer'!B1 -> Transfer from quotation to project | E3: ='Quotation transfer'!B4 -> Mock General 018 | F3: ='Quotation transfer'!B5 -> Mock General 019 | G3: ='Quotation transfer'!B8 -> Mock General 022 | H3: ='Quotation transfer'!B9 -> Mock General 023 | I3: Quotation transfer
B4: WP1.1. | C4: =C3 -> Project Management preparation | D4: ='Draft Timing'!B1 -> Define preliminary timing | E4: ='Draft Timing'!B4 -> Mock General 028 | F4: ='Draft Timing'!B5 -> Mock General 029 | G4: ='Draft Timing'!B8 -> Mock General 032 | H4: ='Draft Timing'!B9 -> Mock General 033 | I4: Draft Timing
B5: WP1.1. | C5: =C4 -> Project Management preparation | D5: ='Team & Resources'!B1 -> Define and confirm team members and resources | E5: ='Team & Resources'!B4 -> Mock General 038 | F5: ='Team & Resources'!B5 -> Mock General 039 | G5: ='Team & Resources'!B8 -> Mock General 042 | H5: ='Team & Resources'!B9 -> Mock General 043 | I5: Team & Resources
B6: WP1.1. | C6: =C5 -> Project Management preparation | D6: =Softwares!B1 -> Initiate softwares | E6: =Softwares!B4 -> Mock General 048 | F6: =Softwares!B5 -> Mock General 049 | G6: =Softwares!B8 -> Mock General 052 | H6: =Softwares!B9 -> Mock General 053 | I6: Softwares
B7: WP1.1. | C7: =C6 -> Project Management preparation | D7: ='Proj Data Draft'!B1 -> Prepare preliminary project data and targets | E7: ='Proj Data Draft'!B4 -> Mock General 058 | F7: ='Proj Data Draft'!B5 -> Mock General 059 | G7: ='Proj Data Draft'!B8 -> Mock General 062 | H7: ='Proj Data Draft'!B9 -> Mock General 063 | I7: Proj Data Draft
A8: Phase 1 | B8: M1 | C8: ='ph1 m1. PJ K-OFF'!B1 -> Project Kick-off | D8: ='ph1 m1. PJ K-OFF'!B1 -> Project Kick-off | E8: ='ph1 m1. PJ K-OFF'!B4 -> Mock General 068 | F8: ='ph1 m1. PJ K-OFF'!B5 -> Mock General 069 | G8: ='ph1 m1. PJ K-OFF'!B8 -> Mock General 072 | H8: ='ph1 m1. PJ K-OFF'!B9 -> Mock General 073 | I8: M1. PJ K-OFF
B9: M1 | C9: =C8 -> Project Kick-off | D9: ='Risk mgt Ph1'!B1 -> Risk Management | E9: ='Risk mgt Ph1'!B4 -> Mock General 079 | F9: ='Risk mgt Ph1'!B5 -> Mock General 080 | G9: ='Risk mgt Ph1'!B8 -> Mock General 083 | H9: ='Risk mgt Ph1'!B9 -> Mock General 084 | I9: Risk mgt Ph1
B10: M1 | C10: =C9 -> Project Kick-off | D10: ='Proj Data Ph1'!B1 -> Target Data Confirmation | E10: ='Proj Data Ph1'!B4 -> Mock General 089 | F10: ='Proj Data Ph1'!B5 -> Mock General 090 | G10: ='Proj Data Ph1'!B8 -> Mock General 093 | H10: ='Proj Data Ph1'!B9 -> Mock General 094 | I10: Proj Data Ph1
B11: M1 | C11: =C10 -> Project Kick-off | D11: ='LLC Ph1'!B1 -> Identify the reference projects | E11: ='LLC Ph1'!B4 -> Mock General 099 | F11: ='LLC Ph1'!B5 -> Mock General 100 | G11: ='LLC Ph1'!B8 -> Mock General 103 | H11: ='LLC Ph1'!B9 -> Mock General 104 | I11: LLC Ph1
A12: Phase 2 | B12: WP 2.0 | C12: ='WP Proto tool pha'!B1 -> Prototype tool phase | D12: ='WP Proto tool pha'!B1 -> Prototype tool phase | E12: ='WP Proto tool pha'!B4 -> Mock General 109 | F12: ='WP Proto tool pha'!B5 -> Mock General 110 | G12: ='WP Proto tool pha'!B8 -> Mock General 113 | H12: ='WP Proto tool pha'!B9 -> Mock General 114 | I12: WP Proto tool pha'!A1
B13: WP 2.0 | C13: =C12 -> Prototype tool phase | D13: ='proto_customer req'!B1 -> Get customer information and requirements | E13: ='proto_customer req'!B4 -> Mock General 119 | F13: ='proto_customer req'!B5 -> Mock General 120 | G13: ='proto_customer req'!B8 -> Mock General 123 | H13: ='proto_customer req'!B9 -> Mock General 124 | I13: proto_customer req'!A1
B14: WP 2.0 | C14: =C13 -> Prototype tool phase | D14: ='Proto fea_Risk analysis'!B1 -> Prototype Feasibility & Risk Analysis | E14: ='Proto fea_Risk analysis'!B4 -> Mock General 129 | F14: ='Proto fea_Risk analysis'!B5 -> Mock General 130 | G14: ='Proto fea_Risk analysis'!B8 -> Mock General 133 | H14: ='Proto fea_Risk analysis'!B9 -> Mock General 134 | I14: Proto fea_Risk analysis'!A1
B15: WP 2.0 | C15: =C14 -> Prototype tool phase | D15: ='3D def'!B1 -> 3D data proto definition | E15: ='3D def'!B4 -> Mock General 139 | F15: ='3D def'!B5 -> Mock General 140 | G15: ='3D def'!B8 -> Mock General 143 | H15: ='3D def'!B9 -> Mock General 144 | I15: 3D def'!A1
B16: WP 2.0 | C16: =C15 -> Prototype tool phase | D16: ='Proto constr'!B1 -> Proto tool construction | E16: ='Proto constr'!B4 -> Mock General 149 | F16: ='Proto constr'!B5 -> Mock General 150 | G16: ='Proto constr'!B8 -> Mock General 153 | H16: ='Proto constr'!B9 -> Mock General 154 | I16: Proto constr'!A1
B17: WP 2.0 | C17: =C16 -> Prototype tool phase | D17: ='Process jigs'!B1 -> Process Proto jigs Construction | E17: ='Process jigs'!B4 -> Mock General 159 | F17: ='Process jigs'!B5 -> Mock General 160 | G17: ='Process jigs'!B8 -> Mock General 163 | H17: ='Process jigs'!B9 -> Mock General 164 | I17: Process jigs'!A1
B18: WP 2.0 | C18: =C17 -> Prototype tool phase | D18: ='material supply'!B1 -> Material supply | E18: ='material supply'!B4 -> Mock General 169 | F18: ='material supply'!B5 -> Mock General 170 | G18: ='material supply'!B8 -> Mock General 173 | H18: ='material supply'!B9 -> Mock General 174 | I18: material supply'!A1
B19: WP 2.0 | C19: =C18 -> Prototype tool phase | D19: ='proto mfg_prodimprov'!B1 -> Proto parts Manufacturing & Product improvement | E19: ='proto mfg_prodimprov'!B4 -> Mock General 179 | F19: ='proto mfg_prodimprov'!B5 -> Mock General 180 | G19: ='proto mfg_prodimprov'!B8 -> Mock General 183 | H19: ='proto mfg_prodimprov'!B9 -> Mock General 184 | I19: proto mfg_prodimprov'!A1
B20: WP 2.0 | C20: =C19 -> Prototype tool phase | D20: =proto_verif_val!B1 -> Prototypes verification/Validation - DV | E20: =proto_verif_val!B4 -> Mock General 189 | F20: =proto_verif_val!B5 -> Mock General 190 | G20: =proto_verif_val!B8 -> Mock General 193 | H20: =proto_verif_val!B9 -> Mock General 194 | I20: proto_verif_val!A1
B21: WP 2.0 | C21: =C20 -> Prototype tool phase | D21: ='design val_proto'!B1 -> Design validation for serial product | E21: ='design val_proto'!B4 -> Mock General 199 | F21: ='design val_proto'!B5 -> Mock General 200 | G21: ='design val_proto'!B8 -> Mock General 203 | H21: ='design val_proto'!B9 -> Mock General 204 | I21: design val_proto'!A1
A22: Phase 2 | B22: WP2.1. | C22: ='WP2.1. PD DEF'!B1 -> Product definition | D22: ='WP2.1. PD DEF'!B1 -> Product definition | E22: ='WP2.1. PD DEF'!B4 -> Mock General 209 | F22: ='WP2.1. PD DEF'!B5 -> Mock General 210 | G22: ='WP2.1. PD DEF'!B8 -> Mock General 213 | H22: ='WP2.1. PD DEF'!B9 -> Mock General 214 | I22: WP2.1. PD DEF
B23: WP2.1. | C23: =C22 -> Product definition | D23: ='Prod requirements'!B1 -> Get customer information and requirements | E23: ='Prod requirements'!B4 -> Mock General 219 | F23: ='Prod requirements'!B5 -> Mock General 220 | G23: ='Prod requirements'!B8 -> Mock General 223 | H23: ='Prod requirements'!B9 -> Mock General 224 | I23: Prod requirements
B24: WP2.1. | C24: =C23 -> Product definition | D24: ='Prod Feasibility'!B1 -> Product Feasibility | E24: ='Prod Feasibility'!B4 -> Mock General 229 | F24: ='Prod Feasibility'!B5 -> Mock General 230 | G24: ='Prod Feasibility'!B8 -> Mock General 233 | H24: ='Prod Feasibility'!B9 -> Mock General 234 | I24: Prod Feasibility
B25: WP2.1. | C25: =C24 -> Product definition | D25: ='Style Frozen'!B1 -> Style frozen | E25: ='Style Frozen'!B4 -> Mock General 239 | F25: ='Style Frozen'!B5 -> Mock General 240 | G25: ='Style Frozen'!B8 -> Mock General 243 | H25: ='Style Frozen'!B9 -> Mock General 244 | I25: Style Frozen
B26: WP2.1. | C26: =C25 -> Product definition | D26: =FEA!B1 -> FEA validation | E26: =FEA!B4 -> Mock General 249 | F26: =FEA!B5 -> Mock General 250 | G26: =FEA!B8 -> Mock General 253 | H26: =FEA!B9 -> Mock General 254 | I26: FEA
B27: WP2.1. | C27: =C26 -> Product definition | D27: ='Purchase elements def'!B1 -> Purchase elements definition | E27: ='Purchase elements def'!B4 -> Mock General 259 | F27: ='Purchase elements def'!B5 -> Mock General 260 | G27: ='Purchase elements def'!B8 -> Mock General 263 | H27: ='Purchase elements def'!B9 -> Mock General 264 | I27: Purchase elements def
B28: WP2.1. | C28: =C27 -> Product definition | D28: =DFMEA!B1 -> DFMEA and related activities | E28: =DFMEA!B4 -> Mock General 269 | F28: =DFMEA!B5 -> Mock General 270 | G28: =DFMEA!B8 -> Mock General 273 | H28: =DFMEA!B9 -> Mock General 274 | I28: DFMEA
B29: WP2.1. | C29: =C28 -> Product definition | D29: ='3D'!B1 -> 3D data submission | E29: ='3D'!B4 -> Mock General 279 | F29: ='3D'!B5 -> Mock General 280 | G29: ='3D'!B8 -> Mock General 283 | H29: ='3D'!B9 -> Mock General 284 | I29: 3D
B30: WP2.1. | C30: =C29 -> Product definition | D30: =DWG!B1 -> Drawings definition | E30: =DWG!B4 -> Mock General 289 | F30: =DWG!B5 -> Mock General 290 | G30: =DWG!B8 -> Mock General 293 | H30: =DWG!B9 -> Mock General 294 | I30: DWG
B31: WP2.1. | C31: =C29 -> Product definition | D31: ='3D Approval'!B1 -> Client approval (3D) | E31: ='3D Approval'!B4 -> Mock General 299 | F31: ='3D Approval'!B5 -> Mock General 300 | G31: ='3D Approval'!B8 -> Mock General 303 | H31: ='3D Approval'!B9 -> Mock General 304 | I31: 3D Approval
B32: WP2.1. | C32: =C31 -> Product definition | D32: ='Drawing Approval'!B1 -> Client approval (Drawing) | E32: ='Drawing Approval'!B4 -> Mock General 309 | F32: ='Drawing Approval'!B5 -> Mock General 310 | G32: ='Drawing Approval'!B8 -> Mock General 313 | H32: ='Drawing Approval'!B9 -> Mock General 314 | I32: Drawing Approval
B33: WP2.1. | C33: =C32 -> Product definition | D33: ='Validation Plan'!B1 -> Define validation plan | E33: ='Validation Plan'!B4 -> Mock General 319 | F33: ='Validation Plan'!B5 -> Mock General 320 | G33: ='Validation Plan'!B8 -> Mock General 323 | H33: ='Validation Plan'!B9 -> Mock General 324 | I33: Validation Plan
B34: WP2.1. | C34: =C33 -> Product definition | D34: ='Component Feasibility'!B1 -> Confirm purchasing feasibility components & packaging | E34: ='Component Feasibility'!B4 -> Mock General 329 | F34: ='Component Feasibility'!B5 -> Mock General 330 | G34: ='Component Feasibility'!B8 -> Mock General 333 | H34: ='Component Feasibility'!B9 -> Mock General 334 | I34: Component Feasibility
B35: WP2.1. | C35: =C34 -> Product definition | D35: ='Material Feasibility'!B1 -> Confirm material feasibility | E35: ='Material Feasibility'!B4 -> Mock General 339 | F35: ='Material Feasibility'!B5 -> Mock General 340 | G35: ='Material Feasibility'!B8 -> Mock General 343 | H35: ='Material Feasibility'!B9 -> Mock General 344 | I35: Material Feasibility
B36: WP2.1. | C36: =C35 -> Product definition | D36: ='Inks Feasibility'!B1 -> Confirm purchasing feasibility inks and paints | E36: ='Inks Feasibility'!B4 -> Mock General 349 | F36: ='Inks Feasibility'!B5 -> Mock General 350 | G36: ='Inks Feasibility'!B8 -> Mock General 353 | H36: ='Inks Feasibility'!B9 -> Mock General 354 | I36: Inks Feasibility
A37: Phase 2 | B37: WP2.2. | C37: ='WP2.2. PC DEF'!B1 -> Process definition | D37: ='WP2.2. PC DEF'!B1 -> Process definition | E37: ='WP2.2. PC DEF'!B4 -> Mock General 359 | F37: ='WP2.2. PC DEF'!B5 -> Mock General 360 | G37: ='WP2.2. PC DEF'!B8 -> Mock General 363.1 | H37: ='WP2.2. PC DEF'!B9 -> Mock General 364 | I37: WP2.2. PC DEF
B38: WP2.2. | C38: =C37 -> Process definition | D38: ='Initial Proc Data'!B1 -> Fill-in "Process Master Data" file | E38: ='Initial Proc Data'!B4 -> Mock General 370 | F38: ='Initial Proc Data'!B5 -> Mock General 371 | G38: ='Initial Proc Data'!B8 -> Mock General 374 | H38: ='Initial Proc Data'!B9 -> Mock General 375 | I38: Initial Proc Data
B39: WP2.2. | C39: =C38 -> Process definition | D39: ='EOL RF'!B1 -> EOL RF/optics/heating machine definition | E39: ='EOL RF'!B4 -> Mock General 380 | F39: ='EOL RF'!B5 -> Mock General 381 | G39: ='EOL RF'!B8 -> Mock General 384 | H39: ='EOL RF'!B9 -> Mock General 385 | I39: EOL RF
B40: WP2.2. | C40: =C39 -> Process definition | D40: ='Potential Flows'!B1 -> Definition of possible manufacturing flow charts | E40: ='Potential Flows'!B4 -> Mock General 390 | F40: ='Potential Flows'!B5 -> Mock General 391 | G40: ='Potential Flows'!B8 -> Mock General 394 | H40: ='Potential Flows'!B9 -> Mock General 395 | I40: Potential Flows
...

Sheet WP1.1. PJ PREP
A1: WP 1.1. | B1: Project Management preparation
A2: ='Instr. template'!A2 -> Objective | B2: Mock General 001
A3: ='Instr. template'!A3 -> Input | B3: Mock General 002
A4: ='Instr. template'!A4 -> Responsible | B4: Mock General 003
A5: ='Instr. template'!A5 -> Support/Attendees | B5: Mock General 004
A6: ='Instr. template'!A6 -> How to do | B6: Mock General 005
A7: ='Instr. template'!A7 -> Assessment | B7: Mock General 006
A8: ='Instr. template'!A8 -> Output | B8: Mock General 007
A9: ='Instr. template'!A9 -> Signatures | B9: Mock General 008
A10: ='Instr. template'!A10 -> Special cases | B10: Mock General 009
A11: List of tasks | B11: Mock General 010
B12: Mock General 011
B13: Mock General 012
B14: Mock General 013
B15: Mock General 014
A16: Version number | B16: Mock General 015

Sheet Quotation transfer
A1: Task | B1: Transfer from quotation to project
A2: ='Instr. template'!A2 -> Objective | B2: Mock General 016
A3: ='Instr. template'!A3 -> Input | B3: Mock General 017
A4: ='Instr. template'!A4 -> Responsible | B4: Mock General 018
A5: ='Instr. template'!A5 -> Support/Attendees | B5: Mock General 019
A6: ='Instr. template'!A6 -> How to do | B6: Mock General 020
A7: ='Instr. template'!A7 -> Assessment | B7: Mock General 021
A8: ='Instr. template'!A8 -> Output | B8: Mock General 022
A9: ='Instr. template'!A9 -> Signatures | B9: Mock General 023
A10: ='Instr. template'!A10 -> Special cases | B10: Mock General 024
A11: Version number | B11: Mock General 025

Sheet Draft Timing
A1: Task | B1: Define preliminary timing
A2: ='Instr. template'!A2 -> Objective | B2: Mock General 026
A3: ='Instr. template'!A3 -> Input | B3: Mock General 027
A4: ='Instr. template'!A4 -> Responsible | B4: Mock General 028
A5: ='Instr. template'!A5 -> Support/Attendees | B5: Mock General 029
A6: ='Instr. template'!A6 -> How to do | B6: Mock General 030
A7: ='Instr. template'!A7 -> Assessment | B7: Mock General 031
A8: ='Instr. template'!A8 -> Output | B8: Mock General 032
A9: ='Instr. template'!A9 -> Signatures | B9: Mock General 033
A10: ='Instr. template'!A10 -> Special cases | B10: Mock General 034
A11: ='Instr. template'!A11 -> Version number | B11: Mock General 035

Sheet Team & Resources
A1: Task | B1: Define and confirm team members and resources
A2: ='Instr. template'!A2 -> Objective | B2: Mock General 036
A3: ='Instr. template'!A3 -> Input | B3: Mock General 037
A4: ='Instr. template'!A4 -> Responsible | B4: Mock General 038
A5: ='Instr. template'!A5 -> Support/Attendees | B5: Mock General 039
A6: ='Instr. template'!A6 -> How to do | B6: Mock General 040
A7: ='Instr. template'!A7 -> Assessment | B7: Mock General 041
A8: ='Instr. template'!A8 -> Output | B8: Mock General 042
A9: ='Instr. template'!A9 -> Signatures | B9: Mock General 043
A10: ='Instr. template'!A10 -> Special cases | B10: Mock General 044
A11: ='Instr. template'!A11 -> Version number | B11: Mock General 045

Sheet Softwares
A1: Task | B1: Initiate softwares
A2: ='Instr. template'!A2 -> Objective | B2: Mock General 046
A3: ='Instr. template'!A3 -> Input | B3: Mock General 047
A4: ='Instr. template'!A4 -> Responsible | B4: Mock General 048
A5: ='Instr. template'!A5 -> Support/Attendees | B5: Mock General 049
A6: ='Instr. template'!A6 -> How to do | B6: Mock General 050
A7: ='Instr. template'!A7 -> Assessment | B7: Mock General 051
A8: ='Instr. template'!A8 -> Output | B8: Mock General 052
A9: ='Instr. template'!A9 -> Signatures | B9: Mock General 053
A10: ='Instr. template'!A10 -> Special cases | B10: Mock General 054
A11: ='Instr. template'!A11 -> Version number | B11: Mock General 055

Sheet Proj Data Draft
A1: Task | B1: Prepare preliminary project data and targets
A2: ='Instr. template'!A2 -> Objective | B2: Mock General 056
A3: ='Instr. template'!A3 -> Input | B3: Mock General 057
A4: ='Instr. template'!A4 -> Responsible | B4: Mock General 058
A5: ='Instr. template'!A5 -> Support/Attendees | B5: Mock General 059
A6: ='Instr. template'!A6 -> How to do | B6: Mock General 060
A7: ='Instr. template'!A7 -> Assessment | B7: Mock General 061
A8: ='Instr. template'!A8 -> Output | B8: Mock General 062
A9: ='Instr. template'!A9 -> Signatures | B9: Mock General 063
A10: ='Instr. template'!A10 -> Special cases | B10: Mock General 064
A11: ='Instr. template'!A11 -> Version number | B11: Mock General 065

Sheet ph1 m1. PJ K-OFF
A1: M1 | B1: Project Kick-off
A2: Objective | B2: Mock General 066
A3: Input | B3: Mock General 067
A4: Responsible | B4: Mock General 068
A5: Support/Attendees | B5: Mock General 069
A6: How to do | B6: Mock General 070
A7: Assessment | B7: Mock General 071
A8: Output | B8: Mock General 072
A9: Signatures | B9: Mock General 073
A10: Special cases | B10: Mock General 074
A11: List of tasks | B11: Mock General 075.1
B12: Mock General 075.2
B13: Mock General 075.3
A14: Version number | B14: Mock General 076

Sheet Risk mgt Ph1
A1: Task | B1: Risk Management
A2: ='Instr. template'!A2 -> Objective | B2: Mock General 077
A3: ='Instr. template'!A3 -> Input | B3: Mock General 078
A4: ='Instr. template'!A4 -> Responsible | B4: Mock General 079
A5: ='Instr. template'!A5 -> Support/Attendees | B5: Mock General 080
A6: ='Instr. template'!A6 -> How to do | B6: Mock General 081
A7: ='Instr. template'!A7 -> Assessment | B7: Mock General 082
A8: ='Instr. template'!A8 -> Output | B8: Mock General 083
A9: ='Instr. template'!A9 -> Signatures | B9: Mock General 084
A10: ='Instr. template'!A10 -> Special cases | B10: Mock General 085
A11: ='Instr. template'!A11 -> Version number | B11: Mock General 086

Sheet Proj Data Ph1
A1: Task | B1: Target Data Confirmation
A2: ='Instr. template'!A2 -> Objective | B2: Mock General 087
A3: ='Instr. template'!A3 -> Input | B3: Mock General 088
A4: ='Instr. template'!A4 -> Responsible | B4: Mock General 089
A5: ='Instr. template'!A5 -> Support/Attendees | B5: Mock General 090
A6: ='Instr. template'!A6 -> How to do | B6: Mock General 091
A7: ='Instr. template'!A7 -> Assessment | B7: Mock General 092
A8: ='Instr. template'!A8 -> Output | B8: Mock General 093
A9: ='Instr. template'!A9 -> Signatures | B9: Mock General 094
A10: ='Instr. template'!A10 -> Special cases | B10: Mock General 095
A11: ='Instr. template'!A11 -> Version number | B11: Mock General 096

Sheet LLC Ph1
A1: Task | B1: Identify the reference projects
A2: ='Instr. template'!A2 -> Objective | B2: Mock General 097
A3: ='Instr. template'!A3 -> Input | B3: Mock General 098
A4: ='Instr. template'!A4 -> Responsible | B4: Mock General 099
A5: ='Instr. template'!A5 -> Support/Attendees | B5: Mock General 100
A6: ='Instr. template'!A6 -> How to do | B6: Mock General 101
A7: ='Instr. template'!A7 -> Assessment | B7: Mock General 102
A8: ='Instr. template'!A8 -> Output | B8: Mock General 103
A9: ='Instr. template'!A9 -> Signatures | B9: Mock General 104
A10: ='Instr. template'!A10 -> Special cases | B10: Mock General 105
A11: ='Instr. template'!A11 -> Version number | B11: Mock General 106

Sheet WP Proto tool pha
A1: WP | B1: Prototype tool phase
A2: ='[1]Instr. template'!A2 -> Objective | B2: Mock General 107
A3: ='[1]Instr. template'!A3 -> Input | B3: Mock General 108
A4: ='[1]Instr. template'!A4 -> Responsible | B4: Mock General 109
A5: ='[1]Instr. template'!A5 -> Support/Attendees | B5: Mock General 110
A6: ='[1]Instr. template'!A6 -> How to do | B6: Mock General 111
A7: ='[1]Instr. template'!A7 -> Assessment | B7: Mock General 112
A8: ='[1]Instr. template'!A8 -> Output | B8: Mock General 113
A9: ='[1]Instr. template'!A9 -> Signatures | B9: Mock General 114
A10: ='[1]Instr. template'!A10 -> Special cases | B10: Mock General 115
A11: ='[1]Instr. template'!A11 -> Version number | B11: Mock General 116

Sheet proto_customer req
A1: Task | B1: Get customer information and requirements
A2: Objective | B2: Mock General 117
A3: Input | B3: Mock General 118
A4: Responsible | B4: Mock General 119
A5: Support/Attendees | B5: Mock General 120
A6: How to do | B6: Mock General 121
A7: Assessment | B7: Mock General 122
A8: Output | B8: Mock General 123
A9: Signatures | B9: Mock General 124
A10: Special cases | B10: Mock General 125
A11: Version number | B11: Mock General 126

Sheet Proto fea_Risk analysis
A1: Task | B1: Prototype Feasibility & Risk Analysis
A2: Objective | B2: Mock General 127
A3: Input | B3: Mock General 128
A4: Responsible | B4: Mock General 129
A5: Support/Attendees | B5: Mock General 130
A6: How to do | B6: Mock General 131
A7: Assessment | B7: Mock General 132
A8: Output | B8: Mock General 133
A9: Signatures | B9: Mock General 134
A10: Special cases | B10: Mock General 135
A11: Version number | B11: Mock General 136

Sheet 3D def
A1: Task | B1: 3D data proto definition
A2: Objective | B2: Mock General 137
A3: Input | B3: Mock General 138
A4: Responsible | B4: Mock General 139
A5: Support/Attendees | B5: Mock General 140
A6: How to do | B6: Mock General 141
A7: Assessment | B7: Mock General 142
A8: Output | B8: Mock General 143
A9: Signatures | B9: Mock General 144
A10: Special cases | B10: Mock General 145
A11: Version number | B11: Mock General 146

Sheet Proto constr
A1: Task | B1: Proto tool construction
A2: Objective | B2: Mock General 147
A3: Input | B3: Mock General 148
A4: Responsible | B4: Mock General 149
A5: Support/Attendees | B5: Mock General 150
A6: How to do | B6: Mock General 151
A7: Assessment | B7: Mock General 152
A8: Output | B8: Mock General 153
A9: Signatures | B9: Mock General 154
A10: Special cases | B10: Mock General 155
A11: Version number | B11: Mock General 156

Sheet Process jigs
A1: Task | B1: Process Proto jigs Construction
A2: Objective | B2: Mock General 157
A3: Input | B3: Mock General 158
A4: Responsible | B4: Mock General 159
A5: Support/Attendees | B5: Mock General 160
A6: How to do | B6: Mock General 161
A7: Assessment | B7: Mock General 162
A8: Output | B8: Mock General 163
A9: Signatures | B9: Mock General 164
A10: Special cases | B10: Mock General 165
A11: Version number | B11: Mock General 166

Sheet material supply
A1: Task | B1: Material supply
A2: Objective | B2: Mock General 167
A3: Input | B3: Mock General 168
A4: Responsible | B4: Mock General 169
A5: Support/Attendees | B5: Mock General 170
A6: How to do | B6: Mock General 171
A7: Assessment | B7: Mock General 172
A8: Output | B8: Mock General 173
A9: Signatures | B9: Mock General 174
A10: Special cases | B10: Mock General 175
A11: Version number | B11: Mock General 176

Sheet proto mfg_prodimprov
A1: Task | B1: Proto parts Manufacturing & Product improvement
A2: Objective | B2: Mock General 177
A3: Input | B3: Mock General 178
A4: Responsible | B4: Mock General 179
A5: Support/Attendees | B5: Mock General 180
A6: How to do | B6: Mock General 181
A7: Assessment | B7: Mock General 182
A8: Output | B8: Mock General 183
A9: Signatures | B9: Mock General 184
A10: Special cases | B10: Mock General 185
A11: Version number | B11: Mock General 186

Sheet proto_verif_val
A1: Task | B1: Prototypes verification/Validation - DV
A2: ='Instr. template'!A2 -> Objective | B2: Mock General 187
A3: ='Instr. template'!A3 -> Input | B3: Mock General 188
A4: ='Instr. template'!A4 -> Responsible | B4: Mock General 189
A5: ='Instr. template'!A5 -> Support/Attendees | B5: Mock General 190
A6: ='Instr. template'!A6 -> How to do | B6: Mock General 191
A7: ='Instr. template'!A7 -> Assessment | B7: Mock General 192
A8: ='Instr. template'!A8 -> Output | B8: Mock General 193
A9: ='Instr. template'!A9 -> Signatures | B9: Mock General 194
A10: ='Instr. template'!A10 -> Special cases | B10: Mock General 195
A11: ='Instr. template'!A11 -> Version number | B11: Mock General 196

Sheet design val_proto
A1: Task | B1: Design validation for serial product
A2: Objective | B2: Mock General 197
A3: Input | B3: Mock General 198
A4: Responsible | B4: Mock General 199
A5: Support/Attendees | B5: Mock General 200
A6: How to do | B6: Mock General 201
A7: Assessment | B7: Mock General 202
A8: Output | B8: Mock General 203
A9: Signatures | B9: Mock General 204
A10: Special cases | B10: Mock General 205
A11: Version number | B11: Mock General 206

Sheet WP2.1. PD DEF
A1: WP 2.1. | B1: Product definition
A2: ='Instr. template'!A2 -> Objective | B2: Mock General 207
A3: ='Instr. template'!A3 -> Input | B3: Mock General 208
A4: ='Instr. template'!A4 -> Responsible | B4: Mock General 209
A5: ='Instr. template'!A5 -> Support/Attendees | B5: Mock General 210
A6: ='Instr. template'!A6 -> How to do | B6: Mock General 211
A7: ='Instr. template'!A7 -> Assessment | B7: Mock General 212
A8: ='Instr. template'!A8 -> Output | B8: Mock General 213
A9: ='Instr. template'!A9 -> Signatures | B9: Mock General 214
A10: ='Instr. template'!A10 -> Special cases | B10: Mock General 215
A11: List of tasks | B11: Mock General 216.1
B12: Mock General 216.2
B13: Mock General 216.3
B14: Mock General 216.4
B15: Mock General 216.5
B16: Mock General 216.6
B17: Mock General 216.7
B18: Mock General 216.8
B19: Mock General 216.9
B20: Mock General 216.10
B21: Mock General 216.11
B22: Mock General 216.12
A23: Version number | B23: Mock General 217

Sheet Prod requirements
A1: Task | B1: Get customer information and requirements
A2: Objective | B2: Mock General 217
A3: Input | B3: Mock General 218
A4: Responsible | B4: Mock General 219
A5: Support/Attendees | B5: Mock General 220
A6: How to do | B6: Mock General 221
A7: Assessment | B7: Mock General 222
A8: Output | B8: Mock General 223
A9: Signatures | B9: Mock General 224
A10: Special cases | B10: Mock General 225
A11: Version number | B11: Mock General 226

Sheet Prod Feasibility
A1: Task | B1: Product Feasibility
A2: Objective | B2: Mock General 227
A3: Input | B3: Mock General 228
A4: Responsible | B4: Mock General 229
A5: Support/Attendees | B5: Mock General 230
A6: How to do | B6: Mock General 231
A7: Assessment | B7: Mock General 232
A8: Output | B8: Mock General 233
A9: Signatures | B9: Mock General 234
A10: Special cases | B10: Mock General 235
A11: Version number | B11: Mock General 236

Sheet Style Frozen
A1: Task | B1: Style frozen
A2: Objective | B2: Mock General 237
A3: Input | B3: Mock General 238
A4: Responsible | B4: Mock General 239
A5: Support/Attendees | B5: Mock General 240
A6: How to do | B6: Mock General 241
A7: Assessment | B7: Mock General 242
A8: Output | B8: Mock General 243
A9: Signatures | B9: Mock General 244
A10: Special cases | B10: Mock General 245
A11: Version number | B11: Mock General 246

Sheet FEA
A1: Task | B1: FEA validation
A2: ='Instr. template'!A2 -> Objective | B2: Mock General 247
A3: ='Instr. template'!A3 -> Input | B3: Mock General 248
A4: ='Instr. template'!A4 -> Responsible | B4: Mock General 249
A5: ='Instr. template'!A5 -> Support/Attendees | B5: Mock General 250
A6: ='Instr. template'!A6 -> How to do | B6: Mock General 251
A7: ='Instr. template'!A7 -> Assessment | B7: Mock General 252
A8: ='Instr. template'!A8 -> Output | B8: Mock General 253
A9: ='Instr. template'!A9 -> Signatures | B9: Mock General 254
A10: ='Instr. template'!A10 -> Special cases | B10: Mock General 255
A11: ='Instr. template'!A11 -> Version number | B11: Mock General 256

Sheet Purchase elements def
A1: Task | B1: Purchase elements definition
A2: ='Instr. template'!A2 -> Objective | B2: Mock General 257
A3: ='Instr. template'!A3 -> Input | B3: Mock General 258
A4: ='Instr. template'!A4 -> Responsible | B4: Mock General 259
A5: ='Instr. template'!A5 -> Support/Attendees | B5: Mock General 260
A6: ='Instr. template'!A6 -> How to do | B6: Mock General 261
A7: ='Instr. template'!A7 -> Assessment | B7: Mock General 262
A8: ='Instr. template'!A8 -> Output | B8: Mock General 263
A9: ='Instr. template'!A9 -> Signatures | B9: Mock General 264
A10: ='Instr. template'!A10 -> Special cases | B10: Mock General 265
A11: ='Instr. template'!A11 -> Version number | B11: Mock General 266

Sheet DFMEA
A1: Task | B1: DFMEA and related activities
A2: ='Instr. template'!A2 -> Objective | B2: Mock General 267
A3: ='Instr. template'!A3 -> Input | B3: Mock General 268
A4: ='Instr. template'!A4 -> Responsible | B4: Mock General 269
A5: ='Instr. template'!A5 -> Support/Attendees | B5: Mock General 270
A6: ='Instr. template'!A6 -> How to do | B6: Mock General 271
A7: ='Instr. template'!A7 -> Assessment | B7: Mock General 272
A8: ='Instr. template'!A8 -> Output | B8: Mock General 273
A9: ='Instr. template'!A9 -> Signatures | B9: Mock General 274
A10: ='Instr. template'!A10 -> Special cases | B10: Mock General 275
A11: ='Instr. template'!A11 -> Version number | B11: Mock General 276

Sheet 3D
A1: Task | B1: 3D data submission
A2: ='[2]Instr. template'!A2 -> Objective | B2: Mock General 277
A3: ='[2]Instr. template'!A3 -> Input | B3: Mock General 278
A4: ='[2]Instr. template'!A4 -> Responsible | B4: Mock General 279
A5: ='[2]Instr. template'!A5 -> Support/Attendees | B5: Mock General 280
A6: ='[2]Instr. template'!A6 -> How to do | B6: Mock General 281
A7: ='[2]Instr. template'!A7 -> Assessment | B7: Mock General 282
A8: ='[2]Instr. template'!A8 -> Output | B8: Mock General 283
A9: ='[2]Instr. template'!A9 -> Signatures | B9: Mock General 284
A10: ='[2]Instr. template'!A10 -> Special cases | B10: Mock General 285
A11: ='[2]Instr. template'!A11 -> Version number | B11: Mock General 286

Sheet DWG
A1: Task | B1: Drawings definition
A2: ='[2]Instr. template'!A2 -> Objective | B2: Mock General 287
A3: ='[2]Instr. template'!A3 -> Input | B3: Mock General 288
A4: ='[2]Instr. template'!A4 -> Responsible | B4: Mock General 289
A5: ='[2]Instr. template'!A5 -> Support/Attendees | B5: Mock General 290
A6: ='[2]Instr. template'!A6 -> How to do | B6: Mock General 291
A7: ='[2]Instr. template'!A7 -> Assessment | B7: Mock General 292
A8: ='[2]Instr. template'!A8 -> Output | B8: Mock General 293
A9: ='[2]Instr. template'!A9 -> Signatures | B9: Mock General 294
A10: ='[2]Instr. template'!A10 -> Special cases | B10: Mock General 295
A11: ='[2]Instr. template'!A11 -> Version number | B11: Mock General 296

Sheet 3D Approval
A1: Task | B1: Client approval (3D)
A2: ='Instr. template'!A2 -> Objective | B2: Mock General 297
A3: ='Instr. template'!A3 -> Input | B3: Mock General 298
A4: ='Instr. template'!A4 -> Responsible | B4: Mock General 299
A5: ='Instr. template'!A5 -> Support/Attendees | B5: Mock General 300
A6: ='Instr. template'!A6 -> How to do | B6: Mock General 301
A7: ='Instr. template'!A7 -> Assessment | B7: Mock General 302
A8: ='Instr. template'!A8 -> Output | B8: Mock General 303
A9: ='Instr. template'!A9 -> Signatures | B9: Mock General 304
A10: ='Instr. template'!A10 -> Special cases | B10: Mock General 305
A11: ='Instr. template'!A11 -> Version number | B11: Mock General 306

Sheet Drawing Approval
A1: Task | B1: Client approval (Drawing)
A2: ='Instr. template'!A2 -> Objective | B2: Mock General 307
A3: ='Instr. template'!A3 -> Input | B3: Mock General 308
A4: ='Instr. template'!A4 -> Responsible | B4: Mock General 309
A5: ='Instr. template'!A5 -> Support/Attendees | B5: Mock General 310
A6: ='Instr. template'!A6 -> How to do | B6: Mock General 311
A7: ='Instr. template'!A7 -> Assessment | B7: Mock General 312
A8: ='Instr. template'!A8 -> Output | B8: Mock General 313
A9: ='Instr. template'!A9 -> Signatures | B9: Mock General 314
A10: ='Instr. template'!A10 -> Special cases | B10: Mock General 315
A11: ='Instr. template'!A11 -> Version number | B11: Mock General 316

Sheet Validation Plan
A1: Task | B1: Define validation plan
A2: ='Instr. template'!A2 -> Objective | B2: Mock General 317
A3: ='Instr. template'!A3 -> Input | B3: Mock General 318
A4: ='Instr. template'!A4 -> Responsible | B4: Mock General 319
A5: ='Instr. template'!A5 -> Support/Attendees | B5: Mock General 320
A6: ='Instr. template'!A6 -> How to do | B6: Mock General 321
A7: ='Instr. template'!A7 -> Assessment | B7: Mock General 322
A8: ='Instr. template'!A8 -> Output | B8: Mock General 323
A9: ='Instr. template'!A9 -> Signatures | B9: Mock General 324
A10: ='Instr. template'!A10 -> Special cases | B10: Mock General 325
A11: ='Instr. template'!A11 -> Version number | B11: Mock General 326

Sheet Component Feasibility
A1: Task | B1: Confirm purchasing feasibility components & packaging
A2: ='Instr. template'!A2 -> Objective | B2: Mock General 327
A3: ='Instr. template'!A3 -> Input | B3: Mock General 328
A4: ='Instr. template'!A4 -> Responsible | B4: Mock General 329
A5: ='Instr. template'!A5 -> Support/Attendees | B5: Mock General 330
A6: ='Instr. template'!A6 -> How to do | B6: Mock General 331
A7: ='Instr. template'!A7 -> Assessment | B7: Mock General 332
A8: ='Instr. template'!A8 -> Output | B8: Mock General 333
A9: ='Instr. template'!A9 -> Signatures | B9: Mock General 334
A10: ='Instr. template'!A10 -> Special cases | B10: Mock General 335
A11: ='Instr. template'!A11 -> Version number | B11: Mock General 336

Sheet Material Feasibility
A1: Task | B1: Confirm material feasibility
A2: ='Instr. template'!A2 -> Objective | B2: Mock General 337
A3: ='Instr. template'!A3 -> Input | B3: Mock General 338
A4: ='Instr. template'!A4 -> Responsible | B4: Mock General 339
A5: ='Instr. template'!A5 -> Support/Attendees | B5: Mock General 340
A6: ='Instr. template'!A6 -> How to do | B6: Mock General 341
A7: ='Instr. template'!A7 -> Assessment | B7: Mock General 342
A8: ='Instr. template'!A8 -> Output | B8: Mock General 343
A9: ='Instr. template'!A9 -> Signatures | B9: Mock General 344
A10: ='Instr. template'!A10 -> Special cases | B10: Mock General 345
A11: ='Instr. template'!A11 -> Version number | B11: Mock General 346

Sheet Inks Feasibility
A1: Task | B1: Confirm purchasing feasibility inks and paints
A2: ='Instr. template'!A2 -> Objective | B2: Mock General 347
A3: ='Instr. template'!A3 -> Input | B3: Mock General 348
A4: ='Instr. template'!A4 -> Responsible | B4: Mock General 349
A5: ='Instr. template'!A5 -> Support/Attendees | B5: Mock General 350
A6: ='Instr. template'!A6 -> How to do | B6: Mock General 351
A7: ='Instr. template'!A7 -> Assessment | B7: Mock General 352
A8: ='Instr. template'!A8 -> Output | B8: Mock General 353
A9: ='Instr. template'!A9 -> Signatures | B9: Mock General 354
A10: ='Instr. template'!A10 -> Special cases | B10: Mock General 355
A11: ='Instr. template'!A11 -> Version number | B11: Mock General 356

Sheet WP2.2. PC DEF
A1: WP2.2. | B1: Process definition
A2: ='Instr. template'!A2 -> Objective | B2: Mock General 357
A3: ='Instr. template'!A3 -> Input | B3: Mock General 358
A4: ='Instr. template'!A4 -> Responsible | B4: Mock General 359
A5: ='Instr. template'!A5 -> Support/Attendees | B5: Mock General 360
A6: ='Instr. template'!A6 -> How to do | B6: Mock General 361
A7: ='Instr. template'!A7 -> Assessment | B7: Mock General 362
A8: ='Instr. template'!A8 -> Output | B8: Mock General 363.1 | C8: Mock General 363.2
A9: ='Instr. template'!A9 -> Signatures | B9: Mock General 364
A10: ='Instr. template'!A10 -> Special cases | B10: Mock General 365
A11: List of achievements | B11: Mock General 366.1
B12: Mock General 366.2
B13: Mock General 366.3
B14: Mock General 366.4
B15: Mock General 366.5
B16: Mock General 366.6
B17: Mock General 366.7
B18: Mock General 366.8
A19: Version number | B19: Mock General 367

Sheet Initial Proc Data
A1: Task | B1: Fill-in "Process Master Data" file
A2: ='Instr. template'!A2 -> Objective | B2: Mock General 368
A3: ='Instr. template'!A3 -> Input | B3: Mock General 369
A4: ='Instr. template'!A4 -> Responsible | B4: Mock General 370
A5: ='Instr. template'!A5 -> Support/Attendees | B5: Mock General 371
A6: ='Instr. template'!A6 -> How to do | B6: Mock General 372
A7: ='Instr. template'!A7 -> Assessment | B7: Mock General 373
A8: ='Instr. template'!A8 -> Output | B8: Mock General 374
A9: ='Instr. template'!A9 -> Signatures | B9: Mock General 375
A10: ='Instr. template'!A10 -> Special cases | B10: Mock General 376
A11: ='Instr. template'!A11 -> Version number | B11: Mock General 377

Sheet EOL RF
A1: Task | B1: EOL RF/optics/heating machine definition
A2: ='Instr. template'!A2 -> Objective | B2: Mock General 378
A3: ='Instr. template'!A3 -> Input | B3: Mock General 379
A4: ='Instr. template'!A4 -> Responsible | B4: Mock General 380
A5: ='Instr. template'!A5 -> Support/Attendees | B5: Mock General 381
A6: ='Instr. template'!A6 -> How to do | B6: Mock General 382
A7: ='Instr. template'!A7 -> Assessment | B7: Mock General 383
A8: ='Instr. template'!A8 -> Output | B8: Mock General 384
A9: ='Instr. template'!A9 -> Signatures | B9: Mock General 385
A10: ='Instr. template'!A10 -> Special cases | B10: Mock General 386
A11: ='Instr. template'!A11 -> Version number | B11: Mock General 387

Sheet Potential Flows
A1: Task | B1: Definition of possible manufacturing flow charts
A2: ='Instr. template'!A2 -> Objective | B2: Mock General 388
A3: ='Instr. template'!A3 -> Input | B3: Mock General 389
A4: ='Instr. template'!A4 -> Responsible | B4: Mock General 390
A5: ='Instr. template'!A5 -> Support/Attendees | B5: Mock General 391
A6: ='Instr. template'!A6 -> How to do | B6: Mock General 392
A7: ='Instr. template'!A7 -> Assessment | B7: Mock General 393
A8: ='Instr. template'!A8 -> Output | B8: Mock General 394
A9: ='Instr. template'!A9 -> Signatures | B9: Mock General 395
A10: ='Instr. template'!A10 -> Special cases | B10: Mock General 396
A11: ='Instr. template'!A11 -> Version number | B11: Mock General 397

Sheet Flow Decision
A1: Task | B1: Election of the optimal flow chart
A2: ='Instr. template'!A2 -> Objective | B2: Mock General 398
A3: ='Instr. template'!A3 -> Input | B3: Mock General 399
A4: ='Instr. template'!A4 -> Responsible | B4: Mock General 400
A5: ='Instr. template'!A5 -> Support/Attendees | B5: Mock General 401
A6: ='Instr. template'!A6 -> How to do | B6: Mock General 402
A7: ='Instr. template'!A7 -> Assessment | B7: Mock General 403
A8: ='Instr. template'!A8 -> Output | B8: Mock General 404
A9: ='Instr. template'!A9 -> Signatures | B9: Mock General 405
A10: ='Instr. template'!A10 -> Special cases | B10: Mock General 406
A11: ='Instr. template'!A11 -> Version number | B11: Mock General 407

Sheet Proc needs
A1: Task | B1: Identification of process needs
A2: ='Instr. template'!A2 -> Objective | B2: Mock General 408
A3: ='Instr. template'!A3 -> Input | B3: Mock General 409
A4: ='Instr. template'!A4 -> Responsible | B4: Mock General 410
A5: ='Instr. template'!A5 -> Support/Attendees | B5: Mock General 411
A6: ='Instr. template'!A6 -> How to do | B6: Mock General 412
A7: ='Instr. template'!A7 -> Assessment | B7: Mock General 413
A8: ='Instr. template'!A8 -> Output | B8: Mock General 414
A9: ='Instr. template'!A9 -> Signatures | B9: Mock General 415
A10: ='Instr. template'!A10 -> Special cases | B10: Mock General 416
A11: ='Instr. template'!A11 -> Version number | B11: Mock General 417

Sheet Proc Quality
A1: Task | B1: Confirm the process meets requirements
A2: ='Instr. template'!A2 -> Objective | B2: Mock General 418
A3: ='Instr. template'!A3 -> Input | B3: Mock General 419
A4: ='Instr. template'!A4 -> Responsible | B4: Mock General 420
A5: ='Instr. template'!A5 -> Support/Attendees | B5: Mock General 421
A6: ='Instr. template'!A6 -> How to do | B6: Mock General 422
A7: ='Instr. template'!A7 -> Assessment | B7: Mock General 423
A8: ='Instr. template'!A8 -> Output | B8: Mock General 424
A9: ='Instr. template'!A9 -> Signatures | B9: Mock General 425
A10: ='Instr. template'!A10 -> Special cases | B10: Mock General 426
A11: ='Instr. template'!A11 -> Version number | B11: Mock General 427

Sheet LaunchCP
A1: Task | B1: Launch Control Plan/Product Master Data
A2: ='[3]Instr. template'!A2 -> Objective | B2: Mock General 428
A3: ='[3]Instr. template'!A3 -> Input | B3: Mock General 429
A4: ='[3]Instr. template'!A4 -> Responsible | B4: Mock General 430
A5: ='[3]Instr. template'!A5 -> Support/Attendees | B5: Mock General 431
A6: ='[3]Instr. template'!A6 -> How to do | B6: Mock General 432
A7: ='[3]Instr. template'!A7 -> Assessment | B7: Mock General 433
A8: ='[3]Instr. template'!A8 -> Output | B8: Mock General 434
A9: ='[3]Instr. template'!A9 -> Signatures | B9: Mock General 435
A10: ='[3]Instr. template'!A10 -> Special cases | B10: Mock General 436
A11: ='[3]Instr. template'!A11 -> Version number | B11: Mock General 437

Sheet Proc Criteria
A1: Task | B1: Definition of acceptance criteria for process approval
A2: Objective | B2: Mock General 438
A3: Input | B3: Mock General 439
A4: Responsible | B4: Mock General 440
A5: Support | B5: Mock General 441
A6: How to do | B6: Mock General 442
A7: Assessment | B7: Mock General 443
A8: Output | B8: Mock General 444
A9: Signatures | B9: Mock General 445
A10: Special cases | B10: Mock General 446
A11: Version number | B11: Mock General 447

Sheet FMEA
A1: Task | B1: Process FMEA
A2: ='Instr. template'!A2 -> Objective | B2: Mock General 448
A3: ='Instr. template'!A3 -> Input | B3: Mock General 449
A4: ='Instr. template'!A4 -> Responsible | B4: Mock General 450
A5: ='Instr. template'!A5 -> Support/Attendees | B5: Mock General 451
A6: ='Instr. template'!A6 -> How to do | B6: Mock General 452
A7: ='Instr. template'!A7 -> Assessment | B7: Mock General 453
A8: ='Instr. template'!A8 -> Output | B8: Mock General 454
A9: ='Instr. template'!A9 -> Signatures | B9: Mock General 455
A10: ='Instr. template'!A10 -> Special cases | B10: Mock General 456
A11: ='Instr. template'!A11 -> Version number | B11: Mock General 457

Sheet Conditions
A1: Task | B1: Elaboration of specific technical conditions for equipments and RFQs
A2: ='Instr. template'!A2 -> Objective | B2: Mock General 458
A3: ='Instr. template'!A3 -> Input | B3: Mock General 459
A4: ='Instr. template'!A4 -> Responsible | B4: Mock General 460
A5: ='Instr. template'!A5 -> Support/Attendees | B5: Mock General 461
A6: ='Instr. template'!A6 -> How to do | B6: Mock General 462
A7: ='Instr. template'!A7 -> Assessment | B7: Mock General 463
A8: ='Instr. template'!A8 -> Output | B8: Mock General 464
A9: ='Instr. template'!A9 -> Signatures | B9: Mock General 465
A10: ='Instr. template'!A10 -> Special cases | B10: Mock General 466
A11: ='Instr. template'!A11 -> Version number | B11: Mock General 467

Sheet WP2.3 PJ FEA
A1: WP2.3. | B1: Project feasibility
A2: ='Instr. template'!A2 -> Objective | B2: Mock General 468
A3: ='Instr. template'!A3 -> Input | B3: Mock General 469
A4: ='Instr. template'!A4 -> Responsible | B4: Mock General 470
A5: ='Instr. template'!A5 -> Support/Attendees | B5: Mock General 471
A6: ='Instr. template'!A6 -> How to do | B6: Mock General 472
A7: ='Instr. template'!A7 -> Assessment | B7: Mock General 473
A8: ='Instr. template'!A8 -> Output | B8: Mock General 474
A9: ='Instr. template'!A9 -> Signatures | B9: Mock General 475
A10: ='Instr. template'!A10 -> Special cases | B10: Mock General 476
A11: List of tasks | B11: Mock General 477.1
B12: Mock General 477.2
B13: Mock General 477.3
B14: Mock General 477.4
A15: Version number | B15: Mock General 478

Sheet Workshop
A1: Task | B1: Workshop to agree on Product/Process Design
A2: Objective | B2: Mock General 479
A3: Input | B3: Mock General 480
A4: Responsible | B4: Mock General 481
A5: Support/Attendees | B5: Mock General 482
A6: How to do | B6: Mock General 483
A7: Assessment | B7: Mock General 484
A8: Output | B8: Mock General 485
A9: Signatures | B9: Mock General 486
A10: Special cases | B10: Mock General 487
A11: Version number | B11: Mock General 488

Sheet Plant Capacity
A1: Task | B1: Confirm plant feasibility
A2: ='Instr. template'!A2 -> Objective | B2: Mock General 489
A3: ='Instr. template'!A3 -> Input | B3: Mock General 490
A4: ='Instr. template'!A4 -> Responsible | B4: Mock General 491
